Workbook
Name TemporalityNode2: MainSheet!$AQ$27
Name PowerNode2: MainSheet!$AA$52
Name PowerNode1: MainSheet!$Y$52
Name AttractionNode2: MainSheet!$K$44
Name CreationNode3: MainSheet!$M$27
Name InnovationIsUpgrading: MainSheet!$BN$24
Name CreationNode2: MainSheet!$K$27
Name TemporalityIsUpgrading: MainSheet!$BN$16
Name CreationLevel: MainSheet!$J$15
Name CreationNode1: MainSheet!$I$27
Name ExodusNode1: MainSheet!$Y$33
Name PowerLevel: MainSheet!$Z$40
Name AttractionNode3: MainSheet!$M$44
Name AttractionLevel: MainSheet!$J$32
Name AttractionIsUpgrading: MainSheet!$BN$32
Name AttractionNode1: MainSheet!$I$44
Name CreationIsUpgrading: MainSheet!$BN$37
Name ExodusNode2: MainSheet!$AA$33
Name TemporalityNode1: MainSheet!$AO$27
Name PowerIsUpgrading: MainSheet!$BN$46
Name ExodusIsUpgrading: MainSheet!$BN$9
Name InnovationNode1: MainSheet!$AO$44
Name TemporalityLevel: MainSheet!$AP$15
Name InnovationLevel: MainSheet!$AP$32
Name InnovationNode3: MainSheet!$AS$44
Name PowerNode3: MainSheet!$AC$52
Name ExodusNode3: MainSheet!$AC$33
Name InnovationNode2: MainSheet!$AQ$44
Name ExodusLevel: MainSheet!$Z$24
Name TemporalityNode3: MainSheet!$AS$27
Name PowderNode3: MainSheet!$AC$52

Sheet MainSheet
A1: Please find Adam's Updated version over here https://docs.google.com/spreadsheets/d/1w8pYKnByx0HZIapmNpmXy8eWuCsVg3D74nI79cSocUQ/copy
D5: Unlock Order is forced as follows: | AK5: If you want to look ahead to individual costs, Increase the level in Gems temporarily | BB5: Current Orbs Saved: | BK5: 300000
D6: Exodus 1 -> Cells 1 -> Exodus 2 | V6: Gem of Evolution | BB6: Orbs accumulated this TR: | BK6: 1000000 | BN6: This planner relies on your Gem info to be up to date
D7: -> Temporal 1 -> Innovation 1 -> Temporal 2 | W7: Quality: | Z7: 0 | AB7: =IF(Z7=0, "Unknown", "MAX") -> Unknown
D8: -> Attraction 1 -> Attraction 2 -> Creation 1 | AK8: When you increase a Gem's quality, it's boost becomes visible | BD8: Upgrades | BJ8: Lv | BK8: Cost | BN8: # | BO8: Next Cost | BP8: Sum of Upgrades | BV8: Boost Gained
U9: =IF(Z7>0, "All Gens Bonus", "-- ") -> -- | Z9: 0 | AB9: =IF(Z7>0, "??", "--") -> -- | AE9: =IF(Z7>0, "x?.??", "--") -> -- | AK9: If A Number Goes Over E308, There Will Be An Error. Mostly This Only Happens On Visible Boosts & Can Be Ignored | BD9: Gem of Exodus | BJ9: =Z24 -> 0 | BK9: =AB24 -> 1 | BN9: FALSE | BP9: =IF(ExodusIsUpgrading, IF(ExodusLevel=2, IF(AttractionLevel<3, IF(AND(AttractionLevel=2, AttractionIsUpgrading), StorageLocker!C4, "Error - Att 3 Not yet Unlocked!" ), StorageLocker!C4 ), StorageLocker!C4 ), StorageLocker!C4 ) -> 0
D10: If you can afford anything in this list, and are up to it, | BD10: Cell Bonus | BJ10: =Z26 -> 0 | BK10: =AB26 -> 1 | BN10: 0 | BO10: =1*(1.2^(Z26+BN10))*MAX(1.05^(Z26+BN10-14),1)*MAX(1.1^(Z26+BN10-29),1)*MAX(1.2^(Z26+BN10-39),1) -> 1 | BP10: =IF(BN10<1, 0, IF(ExodusLevel<1, IF(ExodusIsUpgrading=False, "Error - Exodus 1 Not Yet Unlocked", StorageLocker!C5 ), StorageLocker!C5 ) ) -> 0 | BV10: =IF(OR(BN10>0, BN9), ((4^(BN10+BJ10))^(1+((ExodusLevel+BN9)*0.1)-0.1))/AE26, (4^(1))^(1+((ExodusLevel)*0.1)-0.1)) -> 3.4822023
D11: you are forced to buy it before other qualities | BD11: Shard Bonus | BJ11: =Z27 -> 0 | BK11: =AB27 -> 2 | BN11: 0 | BO11: =2*(1.8^(Z27+BN11))*MAX(1.1^(Z27+BN11-14), 1)*MAX(1.2^(Z27+BN11-29), 1)*MAX(1.3^(Z27+BN11-39), 1) -> 2 | BP11: =IF(BN11<1, 0, IF(ExodusLevel<2, IF(OR(ExodusIsUpgrading=False, ExodusLevel<1), "Error - Exodus 2 Not Yet Unlocked", StorageLocker!C6 ), StorageLocker!C6 ) ) -> 0 | BV11: =IF(OR(BN11>0, BN9), ((5^(BN11+BJ11))^(1+((ExodusLevel+BN9)*0.1)-0.1))/AE27, (5^(1))^(1+((ExodusLevel)*0.1)-0.1)) -> 4.2566996
BD12: RP Bonus | BJ12: =Z28 -> 0 | BK12: =AB28 -> 500 | BN12: 0 | BO12: =500*(1.9^(Z28+BN12))*MAX(1.1^(Z28+BN12-14), 1)*MAX(1.2^(Z28+BN12-29), 1)*MAX(1.3^(Z28+BN12-39), 1) -> 500 | BP12: =IF(BN12<1, 0, IF(ExodusLevel<3, IF(OR(ExodusIsUpgrading=False, ExodusLevel<2), "Error - Exodus 3 Not Yet Unlocked", StorageLocker!C7 ), StorageLocker!C7 ) ) -> 0 | BV12: =IF(OR(BN12>0, BN9), ((8^(BN12+BJ12))^(1+((ExodusLevel+BN9)*0.1)-0.1))/AE28, (8^(1))^(1+((ExodusLevel)*0.1)-0.1)) -> 6.4980192
BD13: MP Bonus | BJ13: =Z29 -> 0 | BK13: =AB29 -> 10000 | BN13: 0 | BO13: =10000*(2^(Z29+BN13))*MAX(1.1^(Z29+BN13-14), 1) -> 10000 | BP13: =IF(BN13<1, 0, IF(ExodusLevel<4, IF(OR(ExodusIsUpgrading=False, ExodusLevel<3), "Error - Exodus 4 Not Yet Unlocked", StorageLocker!C8 ), StorageLocker!C8 ) ) -> 0 | BV13: =IF(OR(BN13>0, BN9), ((4^(BN13+BJ13))^(1+((ExodusLevel+BN9)*0.1)-0.1))/AE29, (4^(1))^(1+((ExodusLevel)*0.1)-0.1)) -> 3.4822023
F14: Gem of Creation | AK14: Gem of Temporality | BD14: AP Bonus | BJ14: =Z30 -> 0 | BK14: =AB30 -> 1000000 | BN14: 0 | BO14: =1000000*(2.1^(Z30+BN14)) -> 1000000 | BP14: =IF(BN14<1, 0, IF(ExodusLevel<4, IF(OR(ExodusIsUpgrading=False, ExodusLevel<3), "Error - Exodus 4 Not Yet Unlocked", StorageLocker!C9 ), StorageLocker!C9 ) ) -> 0 | BV14: =IF(OR(BN14>0, BN9), ((1.6^(BN14+BJ14))^(1+((ExodusLevel+BN9)*0.1)-0.1))/AE30, (1.6^(1))^(1+((ExodusLevel)*0.1)-0.1)) -> 1.5265393
G15: Quality: | J15: 0 | L15: =IF(J15=0, 555, IF(J15=1, 200000, IF(J15=2, 400000, "MAX"))) -> 555 | AM15: Quality: | AP15: 0 | AR15: =IF(TemporalityLevel=0, 5, IF(TemporalityLevel=1, 18, IF(TemporalityLevel=2, 3000000000, "MAX"))) -> 5
BD16: Gem of Temporality | BJ16: =AP15 -> 0 | BK16: =AR15 -> 5 | BN16: FALSE | BP16: =IF(TemporalityIsUpgrading, SWITCH(TemporalityLevel, 0, IF(AND(ExodusLevel<2), IF(AND(ExodusLevel=1, ExodusIsUpgrading), StorageLocker!C12, "Error - Exodus 2 Not Yet Unlocked" ), StorageLocker!C12 ), 1, IF(InnovationLevel<1, IF(AND(InnovationLevel=0, InnovationIsUpgrading), StorageLocker!C12, "Error - Innovation 1 Not Yet Unlocked" ), StorageLocker!C12 ), 2, StorageLocker!C12, 3, StorageLocker!C12 ), StorageLocker!C12 ) -> 0
E17: =IF($J$15>0, "All Mechs Caps +", "-- ") -> -- | J17: 0 | L17: =1*(10^J17) -> 1 | O17: =(100000000^J17)^(1 + (CreationLevel*0.1) - 0.1) -> 1 | AK17: =IF(AP15>0, "MP Bonus (LMs)", "-- ") -> -- | AP17: 0 | AR17: =1.5*(1.5^AP17)*MAX(1.01^(AP17-14),1)*MAX(1.02^(AP17-29),1)*MAX(1.03^(AP17-39),1) -> 1.5 | AU17: =(1+(0.01*AP17)*AR48)^(1+(TemporalityLevel*0.1)-0.1) -> 1 | BD17: MP Bonus (LMs) | BJ17: =AP17 -> 0 | BK17: =AR17 -> 1.5 | BN17: 0 | BO17: =1.5*(1.5^(AP17+BN17))*MAX(1.01^(AP17+BN17-14),1)*MAX(1.02^(AP17+BN17-29),1)*MAX(1.03^(AP17+BN17-39),1) -> 1.5 | BP17: =IF(BN17<1, 0, IF(TemporalityLevel<1, IF(TemporalityIsUpgrading=False, "Error - Temporal 1 Not Yet Unlocked", StorageLocker!C13 ), StorageLocker!C13 ) ) -> 0 | BV17: =IF(OR(BN17>0, BN16), ((1+(0.01*(BN17+BJ17))*AR48)^(1+((TemporalityLevel+BN16)*0.1)-0.1))/AU17, ((1+(0.01*(1+BJ17))*AR48)^(1+((TemporalityLevel+BN16)*0.1)-0.1))/AU17) -> 170.10217
E18: =IF($J$15>1, "Hardware Bonus", "-- ") -> -- | J18: 0 | L18: =1000*(3^J18) -> 1000 | O18: =(10^J18)^(1+(CreationLevel*0.1)-0.1) -> 1 | AK18: =IF(AP15>1, "MP Bonus (Ticks)", "-- ") -> -- | AP18: 0 | AR18: =1.5*(4^AP18)*MAX(1.01^(AP18-14), 1)*MAX(1.02^(AP18-29), 1)*MAX(1.03^(AP18-39), 1) -> 1.5 | AU18: =(1+(0.0005*AP18)*AR50)^(1+(TemporalityLevel*0.1)-0.1) -> 1 | BD18: MP Bonus (Ticks) | BJ18: =AP18 -> 0 | BK18: =AR18 -> 1.5 | BN18: 0 | BO18: =1.5*(4^(AP18+BN18))*MAX(1.01^(AP18+BN18-14), 1)*MAX(1.02^(AP18+BN18-29), 1)*MAX(1.03^(AP18+BN18-39), 1) -> 1.5 | BP18: =IF(BN18<1, 0, IF(TemporalityLevel<2, IF(OR(TemporalityIsUpgrading=False, TemporalityLevel<1), "Error - Temporal 2 Not Yet Unlocked", StorageLocker!C14 ), StorageLocker!C14 ) ) -> 0 | BV18: =IF(OR(BN18>0, BN16), ((1+(0.0005*(BN18+BJ18))*AR50)^(1+((TemporalityLevel+BN16)*0.1)-0.1))/AU18, ((1+(0.0005*(1+BJ18))*AR50)^(1+((TemporalityLevel+BN16)*0.1)-0.1))/AU18) -> 34.420182
E19: =IF($J$15>1, "Software Bonus", "-- ") -> -- | J19: 0 | L19: =10000*(4^J19) -> 10000 | O19: =(50^J19)^(1+(CreationLevel*0.1)-0.1) -> 1 | X19: 1 | Y19: FALSE | Z19: 2 | AA19: FALSE | AB19: 3 | AC19: FALSE | AK19: =IF(AP15>2, "MP (Zag Ranks)", "-- ") -> -- | AP19: 0 | AR19: =1000*(100^AP19) -> 1000 | AU19: =((1+(0.35*AP19))^AR57)^(1+(TemporalityLevel*0.1)-0.1) -> 1 | BD19: MP (Zag Ranks) | BJ19: =AP19 -> 0 | BK19: =AR19 -> 1000 | BN19: 0 | BO19: =1000*(100^(AP19+BN19)) -> 1000 | BP19: =IF(BN19<1, 0, IF(TemporalityLevel<3, IF(OR(TemporalityIsUpgrading=False, TemporalityLevel<2), "Error - Temporal 3 Not Yet Unlocked", StorageLocker!C15 ), StorageLocker!C15 ) ) -> 0 | BV19: =IF(OR(BN19>0, BN16), ((1+(0.35*(AP19+BN19)))^AR57)^(1+((TemporalityLevel+BN16)*0.1)-0.1)/AU19, ((1+(0.35*(AP19+1)))^AR57)^(1+((TemporalityLevel)*0.1)-0.1)/AU19) -> 10914994
E20: =IF($J$15>2, "Cells Bonus", "-- ") -> -- | J20: 0 | L20: =50000*(1.8^J20)*MAX(100^(J20-7),1) -> 50000 | O20: =((1+(0.005*J20))^AR51)^(1+(CreationLevel*0.1)-0.1) -> 1 | X20: Gem Nodes | AK20: =IF(AP15>2, "Max LM Levels", "-- ") -> -- | AP20: 0 | AR20: =20000000*(3^AP20) -> 20000000 | AU20: =5*AP20*TemporalityLevel -> 0 | BD20: Max LM Levels | BJ20: =AP20 -> 0 | BK20: =AR20 -> 20000000 | BN20: 0 | BO20: =20000000*(3^(AP20+BN20)) -> 20000000 | BP20: =IF(BN20<1, 0, IF(TemporalityLevel<3, IF(OR(TemporalityIsUpgrading=False, TemporalityLevel<2), "Error - Temporal 3 Not Yet Unlocked", StorageLocker!C16 ), StorageLocker!C16 ) ) -> 0 | BV20: =IF(OR(BN20>0, BN16), 5*(AP20+BN20)*(TemporalityLevel+BN16)-AU20, 5*TemporalityLevel) -> 0
E21: =IF($J$15>2, "MP Bonus", "-- ") -> -- | J21: 0 | L21: =60000*(2.2^J21)*MAX(100^(J21-7),1) -> 60000 | O21: =((1+(0.001*J21))^AR51)^(1+(CreationLevel*0.1)-0.1) -> 1 | AK21: =IF(AP15>2, "MP (Zag Crew)", "-- ") -> -- | AP21: 0 | AR21: =100000*(3^AP21) -> 100000 | AU21: =((1+(0.003*AP21))^AU57)^(1+(TemporalityLevel * 0.1)-0.1) -> 1 | BD21: MP (Zag Crew) | BJ21: =AP21 -> 0 | BK21: =AR21 -> 100000 | BN21: 0 | BO21: =100000*(3^(AP21+BN21)) -> 100000 | BP21: =IF(BN21<1, 0, IF(TemporalityLevel<3, IF(OR(TemporalityIsUpgrading=False, TemporalityLevel<2), "Error - Temporal 3 Not Yet Unlocked", StorageLocker!C17 ), StorageLocker!C17 ) ) -> 0 | BV21: =IF(OR(BN21>0, BN16), ((1+(0.003*(AP21+BN21)))^AU57)^(1+((TemporalityLevel+BN16) * 0.1)-0.1)/AU21, ((1+(0.003*(AP21+1)))^AU57)^(1+((TemporalityLevel) * 0.1)-0.1)/AU21) -> 14.81971
E22: =IF($J$15>2, "Shard Bonus", "-- ") -> -- | J22: 0 | L22: =70000*(2.8^J22)*MAX(100^(J22-7),1) -> 70000 | O22: =((1+(0.001*J22))^AR51)^(1+(CreationLevel*0.1)-0.1) -> 1 | AK22: =IF(AP15>2, "MP Bonus (LRs)", "-- ") -> -- | AP22: 0 | AR22: =10000000000*(7^AP22) -> 10000000000 | AU22: =((1+(0.005*AP22))^AR49)^(1+(TemporalityLevel * 0.1)-0.1) -> 1 | BD22: MP Bonus (LRs) | BJ22: =AP22 -> 0 | BK22: =AR22 -> 10000000000 | BN22: 0 | BO22: =10000000000*(7^(BJ22+BN22)) -> 10000000000 | BP22: =IF(BN22<1, 0, IF(TemporalityLevel<3, IF(OR(TemporalityIsUpgrading=False, TemporalityLevel<2), "Error - Temporal 3 Not Yet Unlocked", StorageLocker!C18 ), StorageLocker!C18 ) ) -> 0 | BV22: =IF(OR(BN22>0, BN16), ((1+(0.005*(AP22+BN22)))^AR49)^(1+((TemporalityLevel+BN16) * 0.1)-0.1)/AU22, ((1+(0.005*(AP22+1)))^AR49)^(1+((TemporalityLevel) * 0.1)-0.1)/AU22) -> 7923.3923
E23: =IF($J$15>2, "Rp Bonus", "-- ") -> -- | J23: 0 | L23: =80000*(3.5^J23)*MAX(100^(J23-7),1) -> 80000 | O23: =((1+(0.0007*J23))^AR51)^(1+(CreationLevel*0.1)-0.1) -> 1 | V23: Gem of Exodus
W24: Quality: | Z24: 0 | AB24: =IF(Z24=0, 1, IF(Z24=1, 5, IF(Z24=2, 5000, IF(Z24=3, 200000, "MAX")))) -> 1 | BD24: Gem of Innovation | BJ24: =AP32 -> 0 | BK24: =AR32 -> 12 | BN24: FALSE | BP24: =IF(InnovationIsUpgrading, SWITCH(InnovationLevel, 0, IF(TemporalityLevel<1, IF(AND(TemporalityLevel=0,TemporalityIsUpgrading), StorageLocker!C21, "Error - Temporal 1 Not Yet Unlocked" ), StorageLocker!C21 ), 1, StorageLocker!C21, 2, StorageLocker!C21 ), StorageLocker!C21 ) -> 0
BD25: Studies/Study | BJ25: =AP34 -> 0 | BK25: =AR34 -> 3 | BN25: 0 | BO25: =3*(2^(AP34+BN25))*MAX(1.1^(AP34+BN25-9),1)*MAX(1.2^(AP34+BN25-19),1)*MAX(1.3^(AP34+BN25-29),1)*MAX(1.4^(AP34+BN25-39),1) -> 3 | BP25: =IF(BN25<1, 0, IF(InnovationLevel<1, IF(InnovationIsUpgrading=False, "Error - Innovation 1 Not Yet Unlocked", StorageLocker!C22 ), StorageLocker!C22 ) ) -> 0 | BV25: =FLOOR(IF(OR(BN25>0, BN24), (2*(AP34+BN25))^(1+((InnovationLevel+BN24)*0.1)-0.1)-AU34, (2*(AP34+1))^(1+((InnovationLevel)*0.1)-0.1)-AU34),1) -> 1
U26: =IF(Z24>0, "Cells Bonus", "-- ") -> -- | Z26: 0 | AB26: =1*(1.2^Z26)*MAX(1.05^(Z26-14),1)*MAX(1.1^(Z26-29),1)*MAX(1.2^(Z26-39),1) -> 1 | AE26: =(4^Z26)^(1+(ExodusLevel*0.1)-0.1) -> 1 | BD26: Cell Bonus | BJ26: =AP35 -> 0 | BK26: =AR35 -> 1000 | BN26: 0 | BO26: =1000*(10^(AP35+BN26)) -> 1000 | BP26: =IF(BN26<1, 0, IF(InnovationLevel<2, IF(OR(InnovationLevel<1, InnovationIsUpgrading=False), "Error - Innovation 2 Not Yet Unlocked", StorageLocker!C23 ), StorageLocker!C23 ) ) -> 0 | BV26: =IF(OR(BN26>0, BN24), ((1+(0.06*(AP35+BN26)))^AR52)^(1+((InnovationLevel+BN24)*0.1)-0.1)/AU35, ((1+(0.06*(AP35+1)))^AR52)^(1+((InnovationLevel)*0.1)-0.1)/AU35) -> 189.46451
H27: 1 | I27: FALSE | J27: 2 | K27: FALSE | L27: 3 | M27: FALSE | U27: =IF(Z24>1, "Shard Bonus", "-- ") -> -- | Z27: 0 | AB27: =2*(1.8^Z27)*MAX(1.1^(Z27-14), 1)*MAX(1.2^(Z27-29), 1)*MAX(1.3^(Z27-39), 1) -> 2 | AE27: =(5^Z27)^(1+(ExodusLevel*0.1)-0.1) -> 1 | AN27: 1 | AO27: FALSE | AP27: 2 | AQ27: FALSE | AR27: 3 | AS27: FALSE | BD27: MP Bonus | BJ27: =AP36 -> 0 | BK27: =AR36 -> 200000 | BN27: 0 | BO27: =200000*(10^(AP36+BN27)) -> 200000 | BP27: =IF(BN27<1, 0, IF(InnovationLevel<2, IF(OR(InnovationLevel<1, InnovationIsUpgrading=False), "Error - Innovation 2 Not Yet Unlocked", StorageLocker!C24 ), StorageLocker!C24 ) ) -> 0 | BV27: =IF(OR(BN27>0, BN24), ((1+(0.04*(AP36+BN27)))^AR52)^(1+((InnovationLevel+BN24)*0.1)-0.1)/AU36, ((1+(0.04*(AP36+1)))^AR52)^(1+((InnovationLevel)*0.1)-0.1)/AU36) -> 34.119333
H28: Gem Nodes | U28: =IF(Z24>2, "RP Bonus", "-- ") -> -- | Z28: 0 | AB28: =500*(1.9^Z28)*MAX(1.1^(Z28-14), 1)*MAX(1.2^(Z28-29), 1)*MAX(1.3^(Z28-39), 1) -> 500 | AE28: =(8^Z28)^(1+(ExodusLevel*0.1)-0.1) -> 1 | AN28: Gem Nodes | BD28: Shard Bonus | BJ28: =AP37 -> 0 | BK28: =AR37 -> 3000000 | BN28: 0 | BO28: =3000000*(10^(AP37+BN28)) -> 3000000 | BP28: =IF(BN28<1, 0, IF(InnovationLevel<2, IF(OR(InnovationLevel<1, InnovationIsUpgrading=False), "Error - Innovation 2 Not Yet Unlocked", StorageLocker!C25 ), StorageLocker!C25 ) ) -> 0 | BV28: =IF(OR(BN28>0, BN24), ((1+(0.04*(AP37+BN28)))^AR52)^(1+((InnovationLevel+BN24)*0.1)-0.1)/AU37, ((1+(0.04*(AP37+1)))^AR52)^(1+((InnovationLevel)*0.1)-0.1)/AU37) -> 34.119333
V29: =IF(Z24>3, "MP Bonus", "-- ") -> -- | Z29: 0 | AB29: =10000*(2^Z29)*MAX(1.1^(Z29-14), 1) -> 10000 | AE29: =(4^Z29)^(1+(Z24*0.1)-0.1) -> 1 | BD29: RP Bonus | BJ29: =AP38 -> 0 | BK29: =AR38 -> 40000000 | BN29: 0 | BO29: =40000000*(10^(AP38+BN29)) -> 40000000 | BP29: =IF(BN29<1, 0, IF(InnovationLevel<2, IF(OR(InnovationLevel<1, InnovationIsUpgrading=False), "Error - Innovation 2 Not Yet Unlocked", StorageLocker!C26 ), StorageLocker!C26 ) ) -> 0 | BV29: =IF(OR(BN29>0, BN24), ((1+(0.04*(AP38+BN29)))^AR52)^(1+((InnovationLevel+BN24)*0.1)-0.1)/AU38, ((1+(0.04*(AP38+1)))^AR52)^(1+((InnovationLevel)*0.1)-0.1)/AU38) -> 34.119333
V30: =IF(Z24>3, "AP Bonus", "-- ") -> -- | Z30: 0 | AB30: =1000000*(2.1^Z30) -> 1000000 | AE30: =(1.6^Z30)^(1+(Z24*0.1)-0.1) -> 1 | BD30: AP Bonus | BJ30: =AP39 -> 0 | BK30: =AR39 -> 500000000 | BN30: 0 | BO30: =500000000*(10^(AP39+BN30)) -> 500000000 | BP30: =IF(BN30<1, 0, IF(InnovationLevel<2, IF(OR(InnovationLevel<1, InnovationIsUpgrading=False), "Error - Innovation 2 Not Yet Unlocked", StorageLocker!C27 ), StorageLocker!C27 ) ) -> 0 | BV30: =IF(OR(BN30>0, BN24), ((1+(0.04*(AP39+BN30)))^AR52)^(1+((InnovationLevel+BN24)*0.1)-0.1)/AU39, ((1+(0.04*(AP39+1)))^AR52)^(1+((InnovationLevel)*0.1)-0.1)/AU39) -> 34.119333
F31: Gem of Attraction | AL31: Gem of Innovation
G32: Quality: | J32: 0 | L32: =IF(J32=0, 30, IF(J32=1, 150, IF(J32=2, 1000, "MAX"))) -> 30 | AM32: Quality: | AP32: 0 | AR32: =IF(AP32=0, 12, IF(AP32=1, 10000000000, "MAX")) -> 12 | BD32: Gem of Attraction | BJ32: =J32 -> 0 | BK32: =L32 -> 30 | BN32: FALSE | BP32: =IF(AttractionIsUpgrading, SWITCH(AttractionLevel, 0, IF(TemporalityLevel<2, IF(AND(TemporalityLevel=1,TemporalityIsUpgrading), StorageLocker!C30, "Error - Temporal 2 Not Yet Unlocked" ), StorageLocker!C30 ), 2, IF(CreationLevel<1, IF(AND(CreationLevel=0,CreationIsUpgrading), StorageLocker!C30, "Error - Creation 1 Not Yet Unlocked" ), StorageLocker!C30 ), StorageLocker!C30 ), StorageLocker!C30 ) -> 0
BD33: Borge Loot | BJ33: =J34 -> 0 | BK33: =L34 -> 5 | BN33: 0 | BO33: =5*(2.5^(J34+BN33))*MAX(1.2^(J34+BN33-9),1)*MAX(1.3^(J34+BN33-19),1)*MAX(1.4^(J34+BN33-29),1)*MAX(2^(J34+BN33-39),1) -> 5 | BP33: =IF(BN33<1, 0, IF(AttractionLevel<1, IF(AttractionIsUpgrading=False, "Error - Attraction 1 Not Yet Unlocked", StorageLocker!C31 ), StorageLocker!C31 ) ) -> 0 | BV33: =IF(OR(BN33>0, BN32), ((1.07^(BN33+BJ33))^(1+((AttractionLevel+BN32)*0.1)-0.1))/O34, (1.07^(1))^(1+((AttractionLevel+BN32)*0.1)-0.1)) -> 1.062785
E34: =IF(J32>0, "Borge Loot", "-- ") -> -- | J34: 0 | L34: =5*(2.5^J34)*MAX(1.2^(J34-9),1)*MAX(1.3^(J34-19),1)*MAX(1.4^(J34-29),1)*MAX(2^(J34-39),1) -> 5 | O34: =(1.07^J34)^(1+(AttractionLevel*0.1)-0.1) -> 1 | AK34: =IF(AP32>0, "Studies/Study", "-- ") -> -- | AP34: 0 | AR34: =3*(2^AP34)*MAX(1.1^(AP34-9),1)*MAX(1.2^(AP34-19),1)*MAX(1.3^(AP34-29),1)*MAX(1.4^(AP34-39),1) -> 3 | AU34: =FLOOR((2*AP34)^(1+(InnovationLevel*0.1)-0.1),1) -> 0 | BD34: Ozzy Loot | BJ34: =J35 -> 0 | BK34: =L35 -> 20 | BN34: 0 | BO34: =20*(2.5^(J35+BN34))*MAX(1.3^(J35+BN34-9), 1)*MAX(1.4^(J35+BN34-19), 1)*MAX(1.5^(J35+BN34-29), 1)*MAX(1.5^(J35+BN34-39), 1) -> 20 | BP34: =IF(BN34<1, 0, IF(AND(AttractionLevel<2), IF(OR(AttractionIsUpgrading=False, AttractionLevel < 1), "Error - Attraction 2 Not Yet Unlocked", StorageLocker!C32 ), StorageLocker!C32 ) ) -> 0 | BV34: =IF(OR(BN34>0, BN32), ((1.04^(BN34+BJ34))^(1+((AttractionLevel+BN32)*0.1)-0.1))/O35, (1.04^(1))^(1+((AttractionLevel+BN32)*0.1)-0.1)) -> 1.035929
E35: =IF(J32>1, "Ozzy Loot", "-- ") -> -- | J35: 0 | L35: =20*(2.5^J35)*MAX(1.3^(J35-9), 1)*MAX(1.4^(J35-19), 1)*MAX(1.5^(J35-29), 1)*MAX(1.5^(J35-39), 1) -> 20 | O35: =(1.04^J35)^(1+(AttractionLevel*0.1)-0.1) -> 1 | AK35: =IF($AP$32>1, "Cells Bonus", "-- ") -> -- | AP35: 0 | AR35: =1000*(10^AP35) -> 1000 | AU35: =((1+(0.06*AP35))^AR52)^(1+(InnovationLevel*0.1)-0.1) -> 1 | BD35: Catch Up Power | BJ35: =J36 -> 0 | BK35: =L36 -> 1 | BN35: 0 | BO35: =1*(100^(J36+BN35)) -> 1 | BP35: =IF(BN35<1, 0, IF(AND(AttractionLevel<3), IF(OR(AttractionIsUpgrading=False, AttractionLevel < 2), "Error - Attraction 3 Not Yet Unlocked", StorageLocker!C33 ), StorageLocker!C33 ) ) -> 0 | BV35: =IF(OR(BN35>0, BN32), ((1.08^(BN35+BJ35))^(1+((AttractionLevel+BN32)*0.1)-0.1))/O36, (1.08^(1))^(1+((AttractionLevel+BN32)*0.1)-0.1)) -> 1.0717201
E36: =IF(J32>2, "Catch-Up Power", "-- ") -> -- | J36: 0 | L36: =1*(100^J36) -> 1 | O36: =(1.08^J36)^(1+(AttractionLevel*0.1)-0.1) -> 1 | AK36: =IF($AP$32>1, "MP Bonus", "-- ") -> -- | AP36: 0 | AR36: =200000*(10^AP36) -> 200000 | AU36: =((1+(0.04*AP36))^AR52)^(1+(InnovationLevel*0.1)-0.1) -> 1
AK37: =IF($AP$32>1, "Shards Bonus", "-- ") -> -- | AP37: 0 | AR37: =3000000*(10^AP37) -> 3000000 | AU37: =((1+(0.04*AP37))^AR52)^(1+(InnovationLevel*0.1)-0.1) -> 1 | BD37: Gem of Creation | BJ37: =J15 -> 0 | BK37: =L15 -> 555 | BN37: FALSE | BP37: =IF(CreationIsUpgrading, SWITCH(CreationLevel, 0, IF(AttractionLevel<2, IF(AND(AttractionLevel=1,AttractionIsUpgrading), StorageLocker!C36, "Error - Attraction 2 Not Yet Unlocked" ), StorageLocker!C36 ), 1, IF(ExodusLevel<3, IF(AND(ExodusLevel=2,ExodusIsUpgrading), StorageLocker!C36, "Error - Exodus 3 Not Yet Unlocked" ), StorageLocker!C36 ), StorageLocker!C36 ), StorageLocker!C36 ) -> 0
AK38: =IF($AP$32>1, "RP Bonus", "-- ") -> -- | AP38: 0 | AR38: =40000000*(10^AP38) -> 40000000 | AU38: =((1+(0.04*AP38))^AR52)^(1+(InnovationLevel*0.1)-0.1) -> 1 | BD38: Mech Cap Boost | BJ38: =J17 -> 0 | BK38: =L17 -> 1 | BN38: 0 | BO38: =1*(10^(J17+BN38)) -> 1 | BP38: =IF(BN38<1, 0, IF(CreationLevel<1, IF(CreationIsUpgrading=False, "Error - Creation 1 Not Yet Unlocked", StorageLocker!C37 ), StorageLocker!C37 ) ) -> 0 | BV38: =IF(OR(BN38>0, BN37), ((100000000^(BN38+BJ38))^(1+((CreationLevel+BN37)*0.1)-0.1))/O17, (100000000^(1))^(1+((CreationLevel+BN37)*0.1)-0.1)) -> 15848932
V39: Gem of Power | AK39: =IF($AP$32>1, "AP Bonus", "-- ") -> -- | AP39: 0 | AR39: =500000000*(10^AP39) -> 500000000 | AU39: =((1+(0.04*AP39))^AR52)^(1+(InnovationLevel*0.1)-0.1) -> 1 | BD39: Hardware Bonus | BJ39: =J18 -> 0 | BK39: =L18 -> 1000 | BN39: 0 | BO39: =1000*(3^(J18+BN39)) -> 1000 | BP39: =IF(BN39<1, 0, IF(CreationLevel<2, IF(OR(CreationIsUpgrading=False, CreationLevel<1), "Error - Creation 2 Not Yet Unlocked", StorageLocker!C38 ), StorageLocker!C38 ) ) -> 0 | BV39: =IF(OR(BN39>0, BN37), ((10^(BJ39+BN39))^(1+((CreationLevel+BN37)*0.1)-0.1))/O18, (10^1)^(1+((CreationLevel+BN37)*0.1)-0.1)) -> 7.9432823
W40: Quality: | Z40: 0 | AB40: =IF(Z40=0, 150000000, "MAX") -> 150000000 | BD40: Software Bonus | BJ40: =J19 -> 0 | BK40: =L19 -> 10000 | BN40: 0 | BO40: =10000*(4^(J19+BN40)) -> 10000 | BP40: =IF(BN40<1, 0, IF(CreationLevel<2, IF(OR(CreationIsUpgrading=False, CreationLevel<1), "Error - Creation 2 Not Yet Unlocked", StorageLocker!C39 ), StorageLocker!C39 ) ) -> 0 | BV40: =IF(OR(BN40>0, BN37), ((50^(BJ40+BN40))^(1+((CreationLevel+BN37)*0.1)-0.1))/O19, (50^1)^(1+((CreationLevel+BN37)*0.1)-0.1)) -> 33.812167
BD41: Cells Bonus | BJ41: =J20 -> 0 | BK41: =L20 -> 50000 | BN41: 0 | BO41: =50000*(1.8^(J20+BN41))*MAX(100^(J20+BN41-7),1) -> 50000 | BP41: =IF(BN41<1, 0, IF(CreationLevel<3, IF(OR(CreationIsUpgrading=False, CreationLevel<2), "Error - Creation 3 Not Yet Unlocked", StorageLocker!C40 ), StorageLocker!C40 ) ) -> 0 | BV41: =IF(OR(BN41>0, BN37), (((1+(0.005*(BJ41+BN41)))^AR51)^(1+((CreationLevel+BN37)*0.1)-0.1))/O20, ((1+(0.005*(BJ41+1)))^AR51)^(1+((CreationLevel+BN37)*0.1)-0.1)/O20) -> 3.12288e+19
U42: =IF(Z40>0, "Cradle Power", "-- ") -> -- | Z42: 0 | AB42: =1000000*(3^Z42) -> 1000000 | AE42: =((1+(0.0012*Z42))^$AU$55) * ((1+(0.02*Z42))^$AR$55) ^(1+($Z$40*0.1)-0.1) -> 1 | BD42: MP Bonus | BJ42: =J21 -> 0 | BK42: =L21 -> 60000 | BN42: 0 | BO42: =60000*(2.2^(J21+BN42))*MAX(100^(J21+BN42-7),1) -> 60000 | BP42: =IF(BN42<1, 0, IF(CreationLevel<3, IF(OR(CreationIsUpgrading=False, CreationLevel<2), "Error - Creation 3 Not Yet Unlocked", StorageLocker!C41 ), StorageLocker!C41 ) ) -> 0 | BV42: =IF(OR(BN42>0, BN37), (((1+(0.001*(BJ42+BN42)))^AR51)^(1+((CreationLevel+BN37)*0.1)-0.1))/O21, ((1+(0.001*(BJ42+1)))^AR51)^(1+((CreationLevel+BN37)*0.1)-0.1)/O21) -> 8066.7262
U43: =IF(Z40>0, "Auxesia Power", "-- ") -> -- | Z43: 0 | AB43: =2000000*(4^Z43) -> 2000000 | AE43: =((1+(0.0014*Z43))^$AU$56) * ((1+(0.02*Z43))^$AR$56) ^(1+($Z$40*0.1)-0.1) -> 1 | BD43: Shards Bonus | BJ43: =J22 -> 0 | BK43: =L22 -> 70000 | BN43: 0 | BO43: =70000*(2.8^(J22+BN43))*MAX(100^(J22+BN43-7),1) -> 70000 | BP43: =IF(BN43<1, 0, IF(CreationLevel<3, IF(OR(CreationIsUpgrading=False, CreationLevel<2), "Error - Creation 3 Not Yet Unlocked", StorageLocker!C42 ), StorageLocker!C42 ) ) -> 0 | BV43: =IF(OR(BN43>0, BN37), (((1+(0.001*(BJ43+BN43)))^AR51)^(1+((CreationLevel+BN37)*0.1)-0.1))/O22, ((1+(0.001*(BJ43+1)))^AR51)^(1+((CreationLevel+BN37)*0.1)-0.1)/O22) -> 8066.7262
...

Sheet Exponent Helper
B2: Exponent Converter
B5: Abv | C5: Name | D5: Value
B6: K | C6: Thousand (Kilo) | D6: 1000
B7: M | C7: Million | D7: 1000000
B8: B | C8: Billion | D8: 1000000000
B9: T | C9: Trillion | D9: 1000000000000
B10: Qa | C10: Quadrillion | D10: 1e+15
B11: Qu | C11: Quintillion | D11: 1e+18
B12: Sx | C12: Sextillion | D12: 1e+21
B13: Sp | C13: Septillion | D13: 1e+24
B14: O | C14: Octillion | D14: 1e+27
B15: N | C15: Nonillion | D15: 1e+30
B16: D | C16: Decillion | D16: 1e+33

Sheet StorageLocker
B2: Sum of costs for Levels in an upgrade
B4: Exodus Quality | C4: =IF(MainSheet!BN9 = False, 0, IF(MainSheet!BK9 = "MAX", "Gem is Maxed, Please untick", MainSheet!BK9)) -> 0 | F4: Power Quality | G4: =IF(MainSheet!BN46 = False, 0, IF(MainSheet!BK46 = "MAX", "Gem is Maxed, Please untick", MainSheet!BK46)) -> 0
B5: Cells Bonus | C5: {=IF(MainSheet!BN10>=999, "MAXED", IF(MainSheet!BN10<1, 0, SUM(OFFSET(INDIRECT("'ExodusData'!H" & MATCH(MainSheet!Z26, ExodusData!G:G, 0)), 0, 0, MainSheet!BN10, 1))))} -> 0 | F5: Cradle Power Bonus | G5: {=IF(MainSheet!BN47>=50, "MAXED", IF(MainSheet!BN47<1, 0, SUM(OFFSET(INDIRECT("'PowerData'!H" & MATCH(MainSheet!Z42, PowerData!G:G, 0)), 0, 0, MainSheet!BN47, 1))))} -> 0
B6: Shards Bonus | C6: {=IF(MainSheet!BN11>=999, "MAXED", IF(MainSheet!BN11<1, 0, SUM(OFFSET(INDIRECT("'ExodusData'!L" & MATCH(MainSheet!Z27, ExodusData!K:K, 0)), 0, 0, MainSheet!BN11, 1))))} -> 0 | F6: Aux Power Bonus | G6: {=IF(MainSheet!BN48>=50, "MAXED", IF(MainSheet!BN48<1, 0, SUM(OFFSET(INDIRECT("'PowerData'!L" & MATCH(MainSheet!Z43, PowerData!K:K, 0)), 0, 0, MainSheet!BN48, 1))))} -> 0
B7: RP Bonus | C7: {=IF(MainSheet!BN12>=999, "MAXED", IF(MainSheet!BN12<1, 0, SUM(OFFSET(INDIRECT("'ExodusData'!P" & MATCH(MainSheet!Z28, ExodusData!O:O, 0)), 0, 0, MainSheet!BN12, 1))))} -> 0 | F7: Zag Power Bonus | G7: {=IF(MainSheet!BN49>=50, "MAXED", IF(MainSheet!BN49<1, 0, SUM(OFFSET(INDIRECT("'PowerData'!P" & MATCH(MainSheet!Z44, PowerData!O:O, 0)), 0, 0, MainSheet!BN49, 1))))} -> 0
B8: MP Bonus | C8: {=IF(MainSheet!BN13>=999, "MAXED", IF(MainSheet!BN13<1, 0, SUM(OFFSET(INDIRECT("'ExodusData'!T" & MATCH(MainSheet!Z29, ExodusData!S:S, 0)), 0, 0, MainSheet!BN13, 1))))} -> 0 | F8: Heph Power Bonus | G8: {=IF(MainSheet!BN50>=50, "MAXED", IF(MainSheet!BN50<1, 0, SUM(OFFSET(INDIRECT("'PowerData'!T" & MATCH(MainSheet!Z45, PowerData!S:S, 0)), 0, 0, MainSheet!BN50, 1))))} -> 0
B9: AP Bonus | C9: {=IF(MainSheet!BN14>=999, "MAXED", IF(MainSheet!BN14<1, 0, SUM(OFFSET(INDIRECT("'ExodusData'!W" & MATCH(MainSheet!Z30, ExodusData!V:V, 0)), 0, 0, MainSheet!BN14, 1))))} -> 0 | F9: Dem Power Bonus | G9: {=IF(MainSheet!BN51>=50, "MAXED", IF(MainSheet!BN51<1, 0, SUM(OFFSET(INDIRECT("'PowerData'!X" & MATCH(MainSheet!Z46, PowerData!W:W, 0)), 0, 0, MainSheet!BN51, 1))))} -> 0
F10: Koios Power Bonus | G10: {=IF(MainSheet!BN52>=50, "MAXED", IF(MainSheet!BN52<1, 0, SUM(OFFSET(INDIRECT("'PowerData'!AB" & MATCH(MainSheet!Z47, PowerData!AA:AA, 0)), 0, 0, MainSheet!BN52, 1))))} -> 0
F11: Zeus Power Bonus | G11: {=IF(MainSheet!BN53>=50, "MAXED", IF(MainSheet!BN53<1, 0, SUM(OFFSET(INDIRECT("'PowerData'!AF" & MATCH(MainSheet!Z48, PowerData!AE:AE, 0)), 0, 0, MainSheet!BN53, 1))))} -> 0
B12: Temporality Quality | C12: =IF(MainSheet!BN16 = False, 0, IF(MainSheet!BK16 = "MAX", "Gem is Maxed, Please untick", MainSheet!BK16)) -> 0 | F12: Bonus Blueprints | G12: {=IF(MainSheet!BN54>=50, "MAXED", IF(MainSheet!BN54<1, 0, SUM(OFFSET(INDIRECT("'PowerData'!AJ" & MATCH(MainSheet!Z49, PowerData!AI:AI, 0)), 0, 0, MainSheet!BN54, 1))))} -> 0
B13: MP(LMs) | C13: {=IF(MainSheet!BN17>=50, "MAXED", IF(MainSheet!BN17<1, 0, SUM(OFFSET(INDIRECT("'TemporalData'!H" & MATCH(MainSheet!AP17, TemporalData!G:G, 0)), 0, 0, MainSheet!BN17, 1))))} -> 0 | F13: Bonus Inno Cores | G13: {=IF(MainSheet!BN55>=50, "MAXED", IF(MainSheet!BN55<1, 0, SUM(OFFSET(INDIRECT("'PowerData'!AN" & MATCH(MainSheet!Z50, PowerData!AM:AM, 0)), 0, 0, MainSheet!BN55, 1))))} -> 0
B14: MP(Ticks) | C14: {=IF(MainSheet!BN18>=50, "MAXED", IF(MainSheet!BN18<1, 0, SUM(OFFSET(INDIRECT("'TemporalData'!L" & MATCH(MainSheet!AP18, TemporalData!K:K, 0)), 0, 0, MainSheet!BN18, 1))))} -> 0
B15: MP(Zag Ranks) | C15: {=IF(MainSheet!BN19>=10, "MAXED", IF(MainSheet!BN19<1, 0, SUM(OFFSET(INDIRECT("'TemporalData'!P" & MATCH(MainSheet!AP19, TemporalData!O:O, 0)), 0, 0, MainSheet!BN19, 1))))} -> 0
B16: LM MAX LEVELS | C16: {=IF(MainSheet!BN20>=100, "MAXED", IF(MainSheet!BN20<1, 0, SUM(OFFSET(INDIRECT("'TemporalData'!T" & MATCH(MainSheet!AP20, TemporalData!S:S, 0)), 0, 0, MainSheet!BN20, 1))))} -> 0
B17: MP(Zag Crew) | C17: {=IF(MainSheet!BN21>=30, "MAXED", IF(MainSheet!BN21<1, 0, SUM(OFFSET(INDIRECT("'TemporalData'!X" & MATCH(MainSheet!AP21, TemporalData!W:W, 0)), 0, 0, MainSheet!BN21, 1))))} -> 0
B18: MP(LRs) | C18: {=IF(MainSheet!BN22>=30, "MAXED", IF(MainSheet!BN22<1, 0, SUM(OFFSET(INDIRECT("'TemporalData'!AB" & MATCH(MainSheet!AP22, TemporalData!AA:AA, 0)), 0, 0, MainSheet!BN22, 1))))} -> 0
B21: Innovation Quality | C21: =IF(MainSheet!BN24 = False, 0, IF(MainSheet!BK24 = "MAX", "Gem is Maxed, Please untick", MainSheet!BK24)) -> 0
B22: Studies/Study | C22: {=IF(MainSheet!BN25>=50, "MAXED", IF(MainSheet!BN25<1, 0, SUM(OFFSET(INDIRECT("'InnovationData'!H" & MATCH(MainSheet!AP34, InnovationData!G:G, 0)), 0, 0, MainSheet!BN25, 1))))} -> 0
B23: Cells Bonus | C23: {=IF(MainSheet!BN26>=50, "MAXED", IF(MainSheet!BN26<1, 0, SUM(OFFSET(INDIRECT("'InnovationData'!L" & MATCH(MainSheet!AP35, InnovationData!K:K, 0)), 0, 0, MainSheet!BN26, 1))))} -> 0
B24: MP Bonus | C24: {=IF(MainSheet!BN27>=50, "MAXED", IF(MainSheet!BN27<1, 0, SUM(OFFSET(INDIRECT("'InnovationData'!P" & MATCH(MainSheet!AP36, InnovationData!O:O, 0)), 0, 0, MainSheet!BN27, 1))))} -> 0
B25: Shards Bonus | C25: {=IF(MainSheet!BN28>=50, "MAXED", IF(MainSheet!BN28<1, 0, SUM(OFFSET(INDIRECT("'InnovationData'!T" & MATCH(MainSheet!AP37, InnovationData!S:S, 0)), 0, 0, MainSheet!BN28, 1))))} -> 0
B26: RP Bonus | C26: {=IF(MainSheet!BN29>=50, "MAXED", IF(MainSheet!BN29<1, 0, SUM(OFFSET(INDIRECT("'InnovationData'!X" & MATCH(MainSheet!AP38, InnovationData!W:W, 0)), 0, 0, MainSheet!BN29, 1))))} -> 0
B27: AP Bonus | C27: {=IF(MainSheet!BN30>=50, "MAXED", IF(MainSheet!BN30<1, 0, SUM(OFFSET(INDIRECT("'InnovationData'!AB" & MATCH(MainSheet!AP39, InnovationData!AA:AA, 0)), 0, 0, MainSheet!BN30, 1))))} -> 0
B30: Attraction Quality | C30: =IF(MainSheet!BN32 = False, 0, IF(MainSheet!BK32 = "MAX", "Gem is Maxed, Please untick", MainSheet!BK32)) -> 0
B31: Borge Loot | C31: {=IF(MainSheet!BN33>=50, "MAXED", IF(MainSheet!BN33<1, 0, SUM(OFFSET(INDIRECT("'AttractionData'!H" & MATCH(MainSheet!J34, AttractionData!G:G, 0)), 0, 0, MainSheet!BN33, 1))))} -> 0
B32: Ozzy Loot | C32: {=IF(MainSheet!BN34>=50, "MAXED", IF(MainSheet!BN34<1, 0, SUM(OFFSET(INDIRECT("'AttractionData'!L" & MATCH(MainSheet!J35, AttractionData!K:K, 0)), 0, 0, MainSheet!BN34, 1))))} -> 0
B33: Catch Up Power | C33: {=IF(MainSheet!BN35>=5, "MAXED", IF(MainSheet!BN35<1, 0, SUM(OFFSET(INDIRECT("'AttractionData'!P" & MATCH(MainSheet!J36, AttractionData!O:O, 0)), 0, 0, MainSheet!BN35, 1))))} -> 0
B36: Creation Quality | C36: =IF(MainSheet!BN37 = False, 0, IF(MainSheet!BK37 = "MAX", "Gem is Maxed, Please untick", MainSheet!BK37)) -> 0
B37: Mech Bonus Cap | C37: {=IF(MainSheet!BN38>=999, "MAXED", IF(MainSheet!BN38<1, 0, SUM(OFFSET(INDIRECT("'CreationData'!H" & MATCH(MainSheet!J17, CreationData!G:G, 0)), 0, 0, MainSheet!BN38, 1))))} -> 0
B38: Hardware Bonus | C38: {=IF(MainSheet!BN39>=20, "MAXED", IF(MainSheet!BN39<1, 0, SUM(OFFSET(INDIRECT("'CreationData'!L" & MATCH(MainSheet!J18, CreationData!K:K, 0)), 0, 0, MainSheet!BN39, 1))))} -> 0
B39: Software Bonus | C39: {=IF(MainSheet!BN40>=20, "MAXED", IF(MainSheet!BN40<1, 0, SUM(OFFSET(INDIRECT("'CreationData'!P" & MATCH(MainSheet!J19, CreationData!O:O, 0)), 0, 0, MainSheet!BN40, 1))))} -> 0
B40: Cells Bonus | C40: {=IF(MainSheet!BN41>=15, "MAXED", IF(MainSheet!BN41<1, 0, SUM(OFFSET(INDIRECT("'CreationData'!T" & MATCH(MainSheet!J20, CreationData!S:S, 0)), 0, 0, MainSheet!BN41, 1))))} -> 0
B41: MP Bonus | C41: {=IF(MainSheet!BN42>=15, "MAXED", IF(MainSheet!BN42<1, 0, SUM(OFFSET(INDIRECT("'CreationData'!X" & MATCH(MainSheet!J21, CreationData!W:W, 0)), 0, 0, MainSheet!BN42, 1))))} -> 0
B42: Shards Bonus | C42: {=IF(MainSheet!BN43>=15, "MAXED", IF(MainSheet!BN43<1, 0, SUM(OFFSET(INDIRECT("'CreationData'!AB" & MATCH(MainSheet!J22, CreationData!AA:AA, 0)), 0, 0, MainSheet!BN43, 1))))} -> 0
B43: Rp Bonus | C43: {=IF(MainSheet!BN44>=15, "MAXED", IF(MainSheet!BN44<1, 0, SUM(OFFSET(INDIRECT("'CreationData'!AF" & MATCH(MainSheet!J23, CreationData!AE:AE, 0)), 0, 0, MainSheet!BN44, 1))))} -> 0

Sheet Ver
A1: 0.1 | B1: Current | F1: Todo:
A2: =IFERROR(__xludf.DUMMYFUNCTION("IF(RAND()>10000, ""Wtf Happened Here???"", IMPORTRANGE(""https://docs.google.com/spreadsheets/d/1imrnzxvC9bD0EeUQlD6YYWSZGM2ux8THzVmRleQmAAU/edit?usp=sharing"", ""Ver!A1""))"),"0.1") -> 0.1 | B2: Latest | F2: Eventually Figure out hidden scaling values on GUs we haven't found yet (If you get any incorrect prices, let me know) - Fix infinity (Mech cap scaling hits it way before max level 999
D3: Changelog - This is local and not updated. The front page change is realtime
D4: This Sheet is no longer maintained. Adam has taken over. Please use his sheet. You can find the link at the top page or in the discord
D5: v0.018 - Corrected Inno 2 Gems in the 'Boost Gained' Field. These were incorrect.
D6: v0.017 - Added Temp 3 & Inno 2 > Along with the 9 new GUs, and inputs required (LRs & Research Levels) - Adjusted Power GU strengths alongside game buffs - Added in indicators for when a GU has hit max level > Not all bonuses work up to there, as normal sheets cap is e308 v0.017a (Thanks Shu) - Fixed Inno 1 reporting as max - Fixed Power GUs not changing colour correctly in input area v0.017b - Added extra x100 scaling per level to the Creation GUs got with update (Post lvl 8) - RP, Not RR. V0.017c - Fixed StorageLocker Inno GUs referencing wrong cells
D7: v0.016 - Added Exodus 4 - Tested as many upgrades as I could to find hidden scalings, thankfuly only found 1 in new GUs so far - Lowered cost of Power GN 2&3 to match game update v0.016a - Fixed the Power outputs in the cart section to the correct scaling factors (missed from the buff update)
D8: v0.015 - v0.0015c - Added Power 1 > Includes 9 new Gem Upgrades - Rearranged sheet a bit to fit new upgrades, you won't be safe to copy from old sheet, will need to input new values > Moved optional inputs such as 'LMs' to below the gem area - Fixed the Exo Cells GU level cap to 999 - Fixed incorrect cell reference causing incorrect 'NextCost' and 'Sum Of Upgrades' - Fixed Creation GN2 cost 1bil -> 500mil > Why did no one tell me this was wrong for so long >.< - Fixed up the goofed 'predictive +1 GU level bonus' for Creation 3 RP (BV:BY35) v0.015d - Updated power bonus scaling to match game update (x1.0012 and x1.02)
D9: v0.014 - Added Creation 2 > Includes Tech Hardware & Software Gem Upgrades - Added Creation 3 > Includes Cells, Mp, Shards, Rp Gem Upgrades - Reformatted sheet to fit more in the boxes - Correct cell references for the new sheet format v0.014a - Added cre3 cells GU cost scaling of 1.8x (Thanks Maya) No current data on hidden cost scaling for new GUs, but considering max levels, probably are not any v0.014b - Corrected the Exodus Cells GU cost scaling within the ExodusData sheet > Should fix incorrect prices post 40 on the planner table
D10: v0.013 - Added the rest of cost scalings currently in the game > Data provided by Chrysto, I'll do up a summary of all increases in Discord v0.013a - Cosmetic Change. Boost Gained will always output at least 1 GU level > If NOT applying relevant upgrades, boost will be red (+1 GU potential) > If applying +1 GU or GQ, boost will be green (Actual Gains) v0.013b - Fixed a bunch of cost errors - Fixed incorrect output on Inno GU
D11: v0.012 - Added some increase cost scalings SamBlaize and I found > Starting at level 15, Shards upgrade increases a further x1.1 per level > Starting at level 15, Mp (LMs) increases a further x1.01 per level > Starting at level 10, Studies increases a further x1.1 per level > > Starting at level 10, Borge Loot increases a further x1.2 per level ~ Chrysto why you hate me :(
D12: v0.011 - Added data to planner to see how much of a boost the upgrades you buy provide > These are to their respective multipliers > Takes into account upgrading a Gem Quality as well
D13: v0.010 - Added Gem Nodes (Descriptions may come later in a seperate tab) - Fixed version indicator that I broke in v0.009 v0.010a - Fixed incorrect costs in StorageLocker due to moving of cells - Framed the outputs section
D14: v0.009 - Added Exodus 3 and Rp Bonuses (Nodes not done yet) - Couple minor changes around the joint - Added rand to version formulas to force update check
... D22: v0.001 -First Release -Added All known Gem Calcs we had v0.001a -Fixed a couple of issues with calcs

Sheet ExodusData
B2: We currently only have 2 quality levels available in Exodus, but the 5 bonuses from icons tells us there will be 5
B4: Exodus Quality Upgrade | G4: Cells Multi Bonus | K4: Shards Multi Bonus | O4: Rp Multi Bonus | S4: MP Multi Bonus | V4: AP Multi Bonus
G6: Base Cost: | H6: 1 | K6: Base Cost: | L6: 2 | O6: Base Cost: | P6: 500 | S6: Base Cost: | T6: 10000 | V6: Base Cost: | W6: 1000000
G7: Cost Multi: | H7: 1.2 | K7: Cost Multi: | L7: 1.8 | O7: Cost Multi: | P7: 1.9 | S7: Cost Multi: | T7: 2 | V7: Cost Multi: | W7: 2.1
B8: Current Level | C8: Cost to Upgrade | D8: Bonus Unlocked | G8: Current Level | H8: Cost to Upgrade | K8: Current Level | L8: Cost to Upgrade | O8: Current Level | P8: Cost to Upgrade | S8: Current Level | T8: Cost to Upgrade | V8: Current Level | W8: Cost to Upgrade
B9: 0 | C9: 1 | D9: Cells Multi | G9: 0 | H9: =$H$6*($H$7^G9)*MAX(1, 1.05^(G9-14))*MAX(1, 1.1^(G9-29))*MAX(1, 1.2^(G9-39)) -> 1 | K9: 0 | L9: =$L$6*($L$7^K9)*MAX(1.1^(K9-14), 1)*MAX(1.2^(K9-29), 1)*MAX(1.3^(K9-39), 1) -> 2 | O9: 0 | P9: =$P$6*($P$7^O9)*MAX(1.1^(O9-14), 1)*MAX(1.2^(O9-29), 1)*MAX(1.3^(O9-39), 1) -> 500 | S9: 0 | T9: =$T$6*($T$7^S9)*MAX(1.1^(S9-14), 1) -> 10000 | V9: 0 | W9: =$W$6*($W$7^V9) -> 1000000
B10: 1 | C10: 5 | D10: Shards Multi | G10: 1 | H10: =$H$6*($H$7^G10)*MAX(1, 1.05^(G10-14))*MAX(1, 1.1^(G10-29))*MAX(1, 1.2^(G10-39)) -> 1.2 | K10: 1 | L10: =$L$6*($L$7^K10)*MAX(1.1^(K10-14), 1)*MAX(1.2^(K10-29), 1)*MAX(1.3^(K10-39), 1) -> 3.6 | O10: 1 | P10: =$P$6*($P$7^O10)*MAX(1.1^(O10-14), 1)*MAX(1.2^(O10-29), 1)*MAX(1.3^(O10-39), 1) -> 950 | S10: 1 | T10: =$T$6*($T$7^S10)*MAX(1.1^(S10-14), 1) -> 20000 | V10: 1 | W10: =$W$6*($W$7^V10) -> 2100000
B11: 2 | C11: 5000 | D11: Rp Multi | G11: 2 | H11: =$H$6*($H$7^G11)*MAX(1, 1.05^(G11-14))*MAX(1, 1.1^(G11-29))*MAX(1, 1.2^(G11-39)) -> 1.44 | K11: 2 | L11: =$L$6*($L$7^K11)*MAX(1.1^(K11-14), 1)*MAX(1.2^(K11-29), 1)*MAX(1.3^(K11-39), 1) -> 6.48 | O11: 2 | P11: =$P$6*($P$7^O11)*MAX(1.1^(O11-14), 1)*MAX(1.2^(O11-29), 1)*MAX(1.3^(O11-39), 1) -> 1805 | S11: 2 | T11: =$T$6*($T$7^S11)*MAX(1.1^(S11-14), 1) -> 40000 | V11: 2 | W11: =$W$6*($W$7^V11) -> 4410000
B12: 3 | C12: 200000 | D12: MP & AP | G12: 3 | H12: =$H$6*($H$7^G12)*MAX(1, 1.05^(G12-14))*MAX(1, 1.1^(G12-29))*MAX(1, 1.2^(G12-39)) -> 1.728 | K12: 3 | L12: =$L$6*($L$7^K12)*MAX(1.1^(K12-14), 1)*MAX(1.2^(K12-29), 1)*MAX(1.3^(K12-39), 1) -> 11.664 | O12: 3 | P12: =$P$6*($P$7^O12)*MAX(1.1^(O12-14), 1)*MAX(1.2^(O12-29), 1)*MAX(1.3^(O12-39), 1) -> 3429.5 | S12: 3 | T12: =$T$6*($T$7^S12)*MAX(1.1^(S12-14), 1) -> 80000 | V12: 3 | W12: =$W$6*($W$7^V12) -> 9261000
G13: 4 | H13: =$H$6*($H$7^G13)*MAX(1, 1.05^(G13-14))*MAX(1, 1.1^(G13-29))*MAX(1, 1.2^(G13-39)) -> 2.0736 | K13: 4 | L13: =$L$6*($L$7^K13)*MAX(1.1^(K13-14), 1)*MAX(1.2^(K13-29), 1)*MAX(1.3^(K13-39), 1) -> 20.9952 | O13: 4 | P13: =$P$6*($P$7^O13)*MAX(1.1^(O13-14), 1)*MAX(1.2^(O13-29), 1)*MAX(1.3^(O13-39), 1) -> 6516.05 | S13: 4 | T13: =$T$6*($T$7^S13)*MAX(1.1^(S13-14), 1) -> 160000 | V13: 4 | W13: =$W$6*($W$7^V13) -> 19448100
G14: 5 | H14: =$H$6*($H$7^G14)*MAX(1, 1.05^(G14-14))*MAX(1, 1.1^(G14-29))*MAX(1, 1.2^(G14-39)) -> 2.48832 | K14: 5 | L14: =$L$6*($L$7^K14)*MAX(1.1^(K14-14), 1)*MAX(1.2^(K14-29), 1)*MAX(1.3^(K14-39), 1) -> 37.79136 | O14: 5 | P14: =$P$6*($P$7^O14)*MAX(1.1^(O14-14), 1)*MAX(1.2^(O14-29), 1)*MAX(1.3^(O14-39), 1) -> 12380.495 | S14: 5 | T14: =$T$6*($T$7^S14)*MAX(1.1^(S14-14), 1) -> 320000 | V14: 5 | W14: =$W$6*($W$7^V14) -> 40841010
G15: 6 | H15: =$H$6*($H$7^G15)*MAX(1, 1.05^(G15-14))*MAX(1, 1.1^(G15-29))*MAX(1, 1.2^(G15-39)) -> 2.985984 | K15: 6 | L15: =$L$6*($L$7^K15)*MAX(1.1^(K15-14), 1)*MAX(1.2^(K15-29), 1)*MAX(1.3^(K15-39), 1) -> 68.024448 | O15: 6 | P15: =$P$6*($P$7^O15)*MAX(1.1^(O15-14), 1)*MAX(1.2^(O15-29), 1)*MAX(1.3^(O15-39), 1) -> 23522.941 | S15: 6 | T15: =$T$6*($T$7^S15)*MAX(1.1^(S15-14), 1) -> 640000 | V15: 6 | W15: =$W$6*($W$7^V15) -> 85766121
G16: 7 | H16: =$H$6*($H$7^G16)*MAX(1, 1.05^(G16-14))*MAX(1, 1.1^(G16-29))*MAX(1, 1.2^(G16-39)) -> 3.5831808 | K16: 7 | L16: =$L$6*($L$7^K16)*MAX(1.1^(K16-14), 1)*MAX(1.2^(K16-29), 1)*MAX(1.3^(K16-39), 1) -> 122.44401 | O16: 7 | P16: =$P$6*($P$7^O16)*MAX(1.1^(O16-14), 1)*MAX(1.2^(O16-29), 1)*MAX(1.3^(O16-39), 1) -> 44693.587 | S16: 7 | T16: =$T$6*($T$7^S16)*MAX(1.1^(S16-14), 1) -> 1280000 | V16: 7 | W16: =$W$6*($W$7^V16) -> 1.8010885e+08
G17: 8 | H17: =$H$6*($H$7^G17)*MAX(1, 1.05^(G17-14))*MAX(1, 1.1^(G17-29))*MAX(1, 1.2^(G17-39)) -> 4.299817 | K17: 8 | L17: =$L$6*($L$7^K17)*MAX(1.1^(K17-14), 1)*MAX(1.2^(K17-29), 1)*MAX(1.3^(K17-39), 1) -> 220.39921 | O17: 8 | P17: =$P$6*($P$7^O17)*MAX(1.1^(O17-14), 1)*MAX(1.2^(O17-29), 1)*MAX(1.3^(O17-39), 1) -> 84917.815 | S17: 8 | T17: =$T$6*($T$7^S17)*MAX(1.1^(S17-14), 1) -> 2560000 | V17: 8 | W17: =$W$6*($W$7^V17) -> 3.7822859e+08
G18: 9 | H18: =$H$6*($H$7^G18)*MAX(1, 1.05^(G18-14))*MAX(1, 1.1^(G18-29))*MAX(1, 1.2^(G18-39)) -> 5.1597804 | K18: 9 | L18: =$L$6*($L$7^K18)*MAX(1.1^(K18-14), 1)*MAX(1.2^(K18-29), 1)*MAX(1.3^(K18-39), 1) -> 396.71858 | O18: 9 | P18: =$P$6*($P$7^O18)*MAX(1.1^(O18-14), 1)*MAX(1.2^(O18-29), 1)*MAX(1.3^(O18-39), 1) -> 161343.85 | S18: 9 | T18: =$T$6*($T$7^S18)*MAX(1.1^(S18-14), 1) -> 5120000 | V18: 9 | W18: =$W$6*($W$7^V18) -> 7.9428005e+08
G19: 10 | H19: =$H$6*($H$7^G19)*MAX(1, 1.05^(G19-14))*MAX(1, 1.1^(G19-29))*MAX(1, 1.2^(G19-39)) -> 6.1917364 | K19: 10 | L19: =$L$6*($L$7^K19)*MAX(1.1^(K19-14), 1)*MAX(1.2^(K19-29), 1)*MAX(1.3^(K19-39), 1) -> 714.09345 | O19: 10 | P19: =$P$6*($P$7^O19)*MAX(1.1^(O19-14), 1)*MAX(1.2^(O19-29), 1)*MAX(1.3^(O19-39), 1) -> 306553.31 | S19: 10 | T19: =$T$6*($T$7^S19)*MAX(1.1^(S19-14), 1) -> 10240000 | V19: 10 | W19: =$W$6*($W$7^V19) -> 1667988098
G20: 11 | H20: =$H$6*($H$7^G20)*MAX(1, 1.05^(G20-14))*MAX(1, 1.1^(G20-29))*MAX(1, 1.2^(G20-39)) -> 7.4300837 | K20: 11 | L20: =$L$6*($L$7^K20)*MAX(1.1^(K20-14), 1)*MAX(1.2^(K20-29), 1)*MAX(1.3^(K20-39), 1) -> 1285.3682 | O20: 11 | P20: =$P$6*($P$7^O20)*MAX(1.1^(O20-14), 1)*MAX(1.2^(O20-29), 1)*MAX(1.3^(O20-39), 1) -> 582451.29 | S20: 11 | T20: =$T$6*($T$7^S20)*MAX(1.1^(S20-14), 1) -> 20480000 | V20: 11 | W20: =$W$6*($W$7^V20) -> 3502775005
G21: 12 | H21: =$H$6*($H$7^G21)*MAX(1, 1.05^(G21-14))*MAX(1, 1.1^(G21-29))*MAX(1, 1.2^(G21-39)) -> 8.9161004 | K21: 12 | L21: =$L$6*($L$7^K21)*MAX(1.1^(K21-14), 1)*MAX(1.2^(K21-29), 1)*MAX(1.3^(K21-39), 1) -> 2313.6628 | O21: 12 | P21: =$P$6*($P$7^O21)*MAX(1.1^(O21-14), 1)*MAX(1.2^(O21-29), 1)*MAX(1.3^(O21-39), 1) -> 1106657.5 | S21: 12 | T21: =$T$6*($T$7^S21)*MAX(1.1^(S21-14), 1) -> 40960000 | V21: 12 | W21: =$W$6*($W$7^V21) -> 7355827511
G22: 13 | H22: =$H$6*($H$7^G22)*MAX(1, 1.05^(G22-14))*MAX(1, 1.1^(G22-29))*MAX(1, 1.2^(G22-39)) -> 10.699321 | K22: 13 | L22: =$L$6*($L$7^K22)*MAX(1.1^(K22-14), 1)*MAX(1.2^(K22-29), 1)*MAX(1.3^(K22-39), 1) -> 4164.593 | O22: 13 | P22: =$P$6*($P$7^O22)*MAX(1.1^(O22-14), 1)*MAX(1.2^(O22-29), 1)*MAX(1.3^(O22-39), 1) -> 2102649.2 | S22: 13 | T22: =$T$6*($T$7^S22)*MAX(1.1^(S22-14), 1) -> 81920000 | V22: 13 | W22: =$W$6*($W$7^V22) -> 15447237774
G23: 14 | H23: =$H$6*($H$7^G23)*MAX(1, 1.05^(G23-14))*MAX(1, 1.1^(G23-29))*MAX(1, 1.2^(G23-39)) -> 12.839185 | K23: 14 | L23: =$L$6*($L$7^K23)*MAX(1.1^(K23-14), 1)*MAX(1.2^(K23-29), 1)*MAX(1.3^(K23-39), 1) -> 7496.2674 | O23: 14 | P23: =$P$6*($P$7^O23)*MAX(1.1^(O23-14), 1)*MAX(1.2^(O23-29), 1)*MAX(1.3^(O23-39), 1) -> 3995033.4 | S23: 14 | T23: =$T$6*($T$7^S23)*MAX(1.1^(S23-14), 1) -> 163840000 | V23: 14 | W23: =$W$6*($W$7^V23) -> 32439199325
G24: 15 | H24: =$H$6*($H$7^G24)*MAX(1, 1.05^(G24-14))*MAX(1, 1.1^(G24-29))*MAX(1, 1.2^(G24-39)) -> 16.177373 | K24: 15 | L24: =$L$6*($L$7^K24)*MAX(1.1^(K24-14), 1)*MAX(1.2^(K24-29), 1)*MAX(1.3^(K24-39), 1) -> 14842.609 | O24: 15 | P24: =$P$6*($P$7^O24)*MAX(1.1^(O24-14), 1)*MAX(1.2^(O24-29), 1)*MAX(1.3^(O24-39), 1) -> 8349619.9 | S24: 15 | T24: =$T$6*($T$7^S24)*MAX(1.1^(S24-14), 1) -> 360448000 | V24: 15 | W24: =$W$6*($W$7^V24) -> 68122318583
... G58: 49 | H58: =$H$6*($H$7^G58)*MAX(1, 1.05^(G58-14))*MAX(1, 1.1^(G58-29))*MAX(1, 1.2^(G58-39)) -> 1742499.6 | K58: 49 | L58: =$L$6*($L$7^K58)*MAX(1.1^(K58-14), 1)*MAX(1.2^(K58-29), 1)*MAX(1.3^(K58-39), 1) -> 9.57602e+16 | O58: 49 | P58: =$P$6*($P$7^O58)*MAX(1.1^(O58-14), 1)*MAX(1.2^(O58-29), 1)*MAX(1.3^(O58-39), 1) -> 3.38609e+20 | S58: 49 | T58: =$T$6*($T$7^S58)*MAX(1.1^(S58-14), 1) -> 1.58203e+20 | V58: 49 | W58: =$W$6*($W$7^V58) -> 6.14816e+21
G59: 50 | H59: =$H$6*($H$7^G59)*MAX(1, 1.05^(G59-14))*MAX(1, 1.1^(G59-29))*MAX(1, 1.2^(G59-39)) -> 2898125.3
G60: 51 | H60: =$H$6*($H$7^G60)*MAX(1, 1.05^(G60-14))*MAX(1, 1.1^(G60-29))*MAX(1, 1.2^(G60-39)) -> 4820162.1
G61: 52 | H61: =$H$6*($H$7^G61)*MAX(1, 1.05^(G61-14))*MAX(1, 1.1^(G61-29))*MAX(1, 1.2^(G61-39)) -> 8016893.5
G62: 53 | H62: =$H$6*($H$7^G62)*MAX(1, 1.05^(G62-14))*MAX(1, 1.1^(G62-29))*MAX(1, 1.2^(G62-39)) -> 13333697
G63: 54 | H63: =$H$6*($H$7^G63)*MAX(1, 1.05^(G63-14))*MAX(1, 1.1^(G63-29))*MAX(1, 1.2^(G63-39)) -> 22176605
G64: 55 | H64: =$H$6*($H$7^G64)*MAX(1, 1.05^(G64-14))*MAX(1, 1.1^(G64-29))*MAX(1, 1.2^(G64-39)) -> 36884130
G65: 56 | H65: =$H$6*($H$7^G65)*MAX(1, 1.05^(G65-14))*MAX(1, 1.1^(G65-29))*MAX(1, 1.2^(G65-39)) -> 61345685
G66: 57 | H66: =$H$6*($H$7^G66)*MAX(1, 1.05^(G66-14))*MAX(1, 1.1^(G66-29))*MAX(1, 1.2^(G66-39)) -> 1.0203014e+08
G67: 58 | H67: =$H$6*($H$7^G67)*MAX(1, 1.05^(G67-14))*MAX(1, 1.1^(G67-29))*MAX(1, 1.2^(G67-39)) -> 1.6969653e+08
G68: 59 | H68: =$H$6*($H$7^G68)*MAX(1, 1.05^(G68-14))*MAX(1, 1.1^(G68-29))*MAX(1, 1.2^(G68-39)) -> 2.8223928e+08
G69: 60 | H69: =$H$6*($H$7^G69)*MAX(1, 1.05^(G69-14))*MAX(1, 1.1^(G69-29))*MAX(1, 1.2^(G69-39)) -> 4.6942037e+08
G70: 61 | H70: =$H$6*($H$7^G70)*MAX(1, 1.05^(G70-14))*MAX(1, 1.1^(G70-29))*MAX(1, 1.2^(G70-39)) -> 7.8073995e+08
... G395: 386 | H395: =$H$6*($H$7^G395)*MAX(1, 1.05^(G395-14))*MAX(1, 1.1^(G395-29))*MAX(1, 1.2^(G395-39)) -> 5.00566e+80

Sheet TemporalData
B4: Temporal Quality Upgrade | G4: MP (LMs) Bonus | K4: MP (Ticks) Bonus | O4: MP Bonus (Zag Rank) | S4: LM MAX LEVELS (Low Tier) | W4: MP Bonus (Zag Crew) | AA4: MP Bonus (LRs)
G6: Base Cost: | H6: 1.5 | K6: Base Cost: | L6: 1.5 | O6: Base Cost: | P6: 1000 | S6: Base Cost: | T6: 20000000 | W6: Base Cost: | X6: 100000 | AA6: Base Cost: | AB6: 10000000000
G7: Cost Multi: | H7: 1.5 | K7: Cost Multi: | L7: 4 | O7: Cost Multi: | P7: 100 | S7: Cost Multi: | T7: 3 | W7: Cost Multi: | X7: 3 | AA7: Cost Multi: | AB7: 7
B8: Current Level | C8: Cost to Upgrade | D8: Bonus Unlocked | G8: Current Level | H8: Cost to Upgrade | K8: Current Level | L8: Cost to Upgrade | O8: Current Level | P8: Cost to Upgrade | S8: Current Level | T8: Cost to Upgrade | W8: Current Level | X8: Cost to Upgrade | AA8: Current Level | AB8: Cost to Upgrade
B9: 0 | C9: 5 | D9: MP (LMs) | G9: 0 | H9: =$H$6*($H$7^G9)*MAX(1.01^(G9-14),1)*MAX(1.02^(G9-29),1)*MAX(1.03^(G9-39),1) -> 1.5 | K9: 0 | L9: =$L$6*($L$7^K9)*MAX(1.01^(K9-14), 1)*MAX(1.02^(K9-29), 1)*MAX(1.03^(K9-39), 1) -> 1.5 | O9: 0 | P9: =$P$6*($P$7^O9) -> 1000 | S9: 0 | T9: =$T$6*($T$7^S9) -> 20000000 | W9: 0 | X9: =$X$6*($X$7^W9) -> 100000 | AA9: 0 | AB9: =$AB$6*($AB$7^AA9) -> 10000000000
B10: 1 | C10: 18 | D10: MP (Ticks) | G10: 1 | H10: =$H$6*($H$7^G10)*MAX(1.01^(G10-14),1)*MAX(1.02^(G10-29),1)*MAX(1.03^(G10-39),1) -> 2.25 | K10: 1 | L10: =$L$6*($L$7^K10)*MAX(1.01^(K10-14), 1)*MAX(1.02^(K10-29), 1)*MAX(1.03^(K10-39), 1) -> 6 | O10: 1 | P10: =$P$6*($P$7^O10) -> 100000 | S10: 1 | T10: =$T$6*($T$7^S10) -> 60000000 | W10: 1 | X10: =$X$6*($X$7^W10) -> 300000 | AA10: 1 | AB10: =$AB$6*($AB$7^AA10) -> 70000000000
B11: 2 | C11: 3000000000 | D11: MP & LM levels | G11: 2 | H11: =$H$6*($H$7^G11)*MAX(1.01^(G11-14),1)*MAX(1.02^(G11-29),1)*MAX(1.03^(G11-39),1) -> 3.375 | K11: 2 | L11: =$L$6*($L$7^K11)*MAX(1.01^(K11-14), 1)*MAX(1.02^(K11-29), 1)*MAX(1.03^(K11-39), 1) -> 24 | O11: 2 | P11: =$P$6*($P$7^O11) -> 10000000 | S11: 2 | T11: =$T$6*($T$7^S11) -> 180000000 | W11: 2 | X11: =$X$6*($X$7^W11) -> 900000 | AA11: 2 | AB11: =$AB$6*($AB$7^AA11) -> 490000000000
G12: 3 | H12: =$H$6*($H$7^G12)*MAX(1.01^(G12-14),1)*MAX(1.02^(G12-29),1)*MAX(1.03^(G12-39),1) -> 5.0625 | K12: 3 | L12: =$L$6*($L$7^K12)*MAX(1.01^(K12-14), 1)*MAX(1.02^(K12-29), 1)*MAX(1.03^(K12-39), 1) -> 96 | O12: 3 | P12: =$P$6*($P$7^O12) -> 1000000000 | S12: 3 | T12: =$T$6*($T$7^S12) -> 540000000 | W12: 3 | X12: =$X$6*($X$7^W12) -> 2700000 | AA12: 3 | AB12: =$AB$6*($AB$7^AA12) -> 3430000000000
G13: 4 | H13: =$H$6*($H$7^G13)*MAX(1.01^(G13-14),1)*MAX(1.02^(G13-29),1)*MAX(1.03^(G13-39),1) -> 7.59375 | K13: 4 | L13: =$L$6*($L$7^K13)*MAX(1.01^(K13-14), 1)*MAX(1.02^(K13-29), 1)*MAX(1.03^(K13-39), 1) -> 384 | O13: 4 | P13: =$P$6*($P$7^O13) -> 100000000000 | S13: 4 | T13: =$T$6*($T$7^S13) -> 1620000000 | W13: 4 | X13: =$X$6*($X$7^W13) -> 8100000 | AA13: 4 | AB13: =$AB$6*($AB$7^AA13) -> 24010000000000
G14: 5 | H14: =$H$6*($H$7^G14)*MAX(1.01^(G14-14),1)*MAX(1.02^(G14-29),1)*MAX(1.03^(G14-39),1) -> 11.390625 | K14: 5 | L14: =$L$6*($L$7^K14)*MAX(1.01^(K14-14), 1)*MAX(1.02^(K14-29), 1)*MAX(1.03^(K14-39), 1) -> 1536 | O14: 5 | P14: =$P$6*($P$7^O14) -> 10000000000000 | S14: 5 | T14: =$T$6*($T$7^S14) -> 4860000000 | W14: 5 | X14: =$X$6*($X$7^W14) -> 24300000 | AA14: 5 | AB14: =$AB$6*($AB$7^AA14) -> 168070000000000
G15: 6 | H15: =$H$6*($H$7^G15)*MAX(1.01^(G15-14),1)*MAX(1.02^(G15-29),1)*MAX(1.03^(G15-39),1) -> 17.085938 | K15: 6 | L15: =$L$6*($L$7^K15)*MAX(1.01^(K15-14), 1)*MAX(1.02^(K15-29), 1)*MAX(1.03^(K15-39), 1) -> 6144 | O15: 6 | P15: =$P$6*($P$7^O15) -> 1e+15 | S15: 6 | T15: =$T$6*($T$7^S15) -> 14580000000 | W15: 6 | X15: =$X$6*($X$7^W15) -> 72900000 | AA15: 6 | AB15: =$AB$6*($AB$7^AA15) -> 1.17649e+15
G16: 7 | H16: =$H$6*($H$7^G16)*MAX(1.01^(G16-14),1)*MAX(1.02^(G16-29),1)*MAX(1.03^(G16-39),1) -> 25.628906 | K16: 7 | L16: =$L$6*($L$7^K16)*MAX(1.01^(K16-14), 1)*MAX(1.02^(K16-29), 1)*MAX(1.03^(K16-39), 1) -> 24576 | O16: 7 | P16: =$P$6*($P$7^O16) -> 1e+17 | S16: 7 | T16: =$T$6*($T$7^S16) -> 43740000000 | W16: 7 | X16: =$X$6*($X$7^W16) -> 218700000 | AA16: 7 | AB16: =$AB$6*($AB$7^AA16) -> 8.23543e+15
G17: 8 | H17: =$H$6*($H$7^G17)*MAX(1.01^(G17-14),1)*MAX(1.02^(G17-29),1)*MAX(1.03^(G17-39),1) -> 38.443359 | K17: 8 | L17: =$L$6*($L$7^K17)*MAX(1.01^(K17-14), 1)*MAX(1.02^(K17-29), 1)*MAX(1.03^(K17-39), 1) -> 98304 | O17: 8 | P17: =$P$6*($P$7^O17) -> 1e+19 | S17: 8 | T17: =$T$6*($T$7^S17) -> 131220000000 | W17: 8 | X17: =$X$6*($X$7^W17) -> 656100000 | AA17: 8 | AB17: =$AB$6*($AB$7^AA17) -> 5.7648e+16
G18: 9 | H18: =$H$6*($H$7^G18)*MAX(1.01^(G18-14),1)*MAX(1.02^(G18-29),1)*MAX(1.03^(G18-39),1) -> 57.665039 | K18: 9 | L18: =$L$6*($L$7^K18)*MAX(1.01^(K18-14), 1)*MAX(1.02^(K18-29), 1)*MAX(1.03^(K18-39), 1) -> 393216 | O18: 9 | P18: =$P$6*($P$7^O18) -> 1e+21 | S18: 9 | T18: =$T$6*($T$7^S18) -> 393660000000 | W18: 9 | X18: =$X$6*($X$7^W18) -> 1968300000 | AA18: 9 | AB18: =$AB$6*($AB$7^AA18) -> 4.03536e+17
G19: 10 | H19: =$H$6*($H$7^G19)*MAX(1.01^(G19-14),1)*MAX(1.02^(G19-29),1)*MAX(1.03^(G19-39),1) -> 86.497559 | K19: 10 | L19: =$L$6*($L$7^K19)*MAX(1.01^(K19-14), 1)*MAX(1.02^(K19-29), 1)*MAX(1.03^(K19-39), 1) -> 1572864 | O19: 10 | P19: MAXED | S19: 10 | T19: =$T$6*($T$7^S19) -> 1180980000000 | W19: 10 | X19: =$X$6*($X$7^W19) -> 5904900000 | AA19: 10 | AB19: =$AB$6*($AB$7^AA19) -> 2.82475e+18
G20: 11 | H20: =$H$6*($H$7^G20)*MAX(1.01^(G20-14),1)*MAX(1.02^(G20-29),1)*MAX(1.03^(G20-39),1) -> 129.74634 | K20: 11 | L20: =$L$6*($L$7^K20)*MAX(1.01^(K20-14), 1)*MAX(1.02^(K20-29), 1)*MAX(1.03^(K20-39), 1) -> 6291456 | S20: 11 | T20: =$T$6*($T$7^S20) -> 3542940000000 | W20: 11 | X20: =$X$6*($X$7^W20) -> 17714700000 | AA20: 11 | AB20: =$AB$6*($AB$7^AA20) -> 1.97733e+19
G21: 12 | H21: =$H$6*($H$7^G21)*MAX(1.01^(G21-14),1)*MAX(1.02^(G21-29),1)*MAX(1.03^(G21-39),1) -> 194.61951 | K21: 12 | L21: =$L$6*($L$7^K21)*MAX(1.01^(K21-14), 1)*MAX(1.02^(K21-29), 1)*MAX(1.03^(K21-39), 1) -> 25165824 | S21: 12 | T21: =$T$6*($T$7^S21) -> 10628820000000 | W21: 12 | X21: =$X$6*($X$7^W21) -> 53144100000 | AA21: 12 | AB21: =$AB$6*($AB$7^AA21) -> 1.38413e+20
G22: 13 | H22: =$H$6*($H$7^G22)*MAX(1.01^(G22-14),1)*MAX(1.02^(G22-29),1)*MAX(1.03^(G22-39),1) -> 291.92926 | K22: 13 | L22: =$L$6*($L$7^K22)*MAX(1.01^(K22-14), 1)*MAX(1.02^(K22-29), 1)*MAX(1.03^(K22-39), 1) -> 100663296 | S22: 13 | T22: =$T$6*($T$7^S22) -> 31886460000000 | W22: 13 | X22: =$X$6*($X$7^W22) -> 159432300000 | AA22: 13 | AB22: =$AB$6*($AB$7^AA22) -> 9.6889e+20
G23: 14 | H23: =$H$6*($H$7^G23)*MAX(1.01^(G23-14),1)*MAX(1.02^(G23-29),1)*MAX(1.03^(G23-39),1) -> 437.89389 | K23: 14 | L23: =$L$6*($L$7^K23)*MAX(1.01^(K23-14), 1)*MAX(1.02^(K23-29), 1)*MAX(1.03^(K23-39), 1) -> 402653184 | S23: 14 | T23: =$T$6*($T$7^S23) -> 95659380000000 | W23: 14 | X23: =$X$6*($X$7^W23) -> 478296900000 | AA23: 14 | AB23: =$AB$6*($AB$7^AA23) -> 6.78223e+21
G24: 15 | H24: =$H$6*($H$7^G24)*MAX(1.01^(G24-14),1)*MAX(1.02^(G24-29),1)*MAX(1.03^(G24-39),1) -> 663.40924 | K24: 15 | L24: =$L$6*($L$7^K24)*MAX(1.01^(K24-14), 1)*MAX(1.02^(K24-29), 1)*MAX(1.03^(K24-39), 1) -> 1626718863 | S24: 15 | T24: =$T$6*($T$7^S24) -> 286978140000000 | W24: 15 | X24: =$X$6*($X$7^W24) -> 1434890700000 | AA24: 15 | AB24: =$AB$6*($AB$7^AA24) -> 4.74756e+22
G25: 16 | H25: =$H$6*($H$7^G25)*MAX(1.01^(G25-14),1)*MAX(1.02^(G25-29),1)*MAX(1.03^(G25-39),1) -> 1005.065 | K25: 16 | L25: =$L$6*($L$7^K25)*MAX(1.01^(K25-14), 1)*MAX(1.02^(K25-29), 1)*MAX(1.03^(K25-39), 1) -> 6571944208 | S25: 16 | T25: =$T$6*($T$7^S25) -> 860934420000000 | W25: 16 | X25: =$X$6*($X$7^W25) -> 4304672100000 | AA25: 16 | AB25: =$AB$6*($AB$7^AA25) -> 3.32329e+23
G26: 17 | H26: =$H$6*($H$7^G26)*MAX(1.01^(G26-14),1)*MAX(1.02^(G26-29),1)*MAX(1.03^(G26-39),1) -> 1522.6735 | K26: 17 | L26: =$L$6*($L$7^K26)*MAX(1.01^(K26-14), 1)*MAX(1.02^(K26-29), 1)*MAX(1.03^(K26-39), 1) -> 26550654600 | S26: 17 | T26: =$T$6*($T$7^S26) -> 2.5828e+15 | W26: 17 | X26: =$X$6*($X$7^W26) -> 12914016300000 | AA26: 17 | AB26: =$AB$6*($AB$7^AA26) -> 2.32631e+24
G27: 18 | H27: =$H$6*($H$7^G27)*MAX(1.01^(G27-14),1)*MAX(1.02^(G27-29),1)*MAX(1.03^(G27-39),1) -> 2306.8503 | K27: 18 | L27: =$L$6*($L$7^K27)*MAX(1.01^(K27-14), 1)*MAX(1.02^(K27-29), 1)*MAX(1.03^(K27-39), 1) -> 107264644585 | S27: 18 | T27: =$T$6*($T$7^S27) -> 7.74841e+15 | W27: 18 | X27: =$X$6*($X$7^W27) -> 38742048900000 | AA27: 18 | AB27: =$AB$6*($AB$7^AA27) -> 1.62841e+25
G28: 19 | H28: =$H$6*($H$7^G28)*MAX(1.01^(G28-14),1)*MAX(1.02^(G28-29),1)*MAX(1.03^(G28-39),1) -> 3494.8782 | K28: 19 | L28: =$L$6*($L$7^K28)*MAX(1.01^(K28-14), 1)*MAX(1.02^(K28-29), 1)*MAX(1.03^(K28-39), 1) -> 433349164123 | S28: 19 | T28: =$T$6*($T$7^S28) -> 2.32452e+16 | W28: 19 | X28: =$X$6*($X$7^W28) -> 116226146700000 | AA28: 19 | AB28: =$AB$6*($AB$7^AA28) -> 1.13989e+26
G29: 20 | H29: =$H$6*($H$7^G29)*MAX(1.01^(G29-14),1)*MAX(1.02^(G29-29),1)*MAX(1.03^(G29-39),1) -> 5294.7405 | K29: 20 | L29: =$L$6*($L$7^K29)*MAX(1.01^(K29-14), 1)*MAX(1.02^(K29-29), 1)*MAX(1.03^(K29-39), 1) -> 1750730623057 | S29: 20 | T29: =$T$6*($T$7^S29) -> 6.97357e+16 | W29: 20 | X29: =$X$6*($X$7^W29) -> 348678440100000 | AA29: 20 | AB29: =$AB$6*($AB$7^AA29) -> 7.97923e+26
G30: 21 | H30: =$H$6*($H$7^G30)*MAX(1.01^(G30-14),1)*MAX(1.02^(G30-29),1)*MAX(1.03^(G30-39),1) -> 8021.5319 | K30: 21 | L30: =$L$6*($L$7^K30)*MAX(1.01^(K30-14), 1)*MAX(1.02^(K30-29), 1)*MAX(1.03^(K30-39), 1) -> 7072951717148 | S30: 21 | T30: =$T$6*($T$7^S30) -> 2.09207e+17 | W30: 21 | X30: =$X$6*($X$7^W30) -> 1.04604e+15 | AA30: 21 | AB30: =$AB$6*($AB$7^AA30) -> 5.58546e+27
G31: 22 | H31: =$H$6*($H$7^G31)*MAX(1.01^(G31-14),1)*MAX(1.02^(G31-29),1)*MAX(1.03^(G31-39),1) -> 12152.621 | K31: 22 | L31: =$L$6*($L$7^K31)*MAX(1.01^(K31-14), 1)*MAX(1.02^(K31-29), 1)*MAX(1.03^(K31-39), 1) -> 28574724937279 | S31: 22 | T31: =$T$6*($T$7^S31) -> 6.27621e+17 | W31: 22 | X31: =$X$6*($X$7^W31) -> 3.13811e+15 | AA31: 22 | AB31: =$AB$6*($AB$7^AA31) -> 3.90982e+28
... G38: 29 | H38: =$H$6*($H$7^G38)*MAX(1.01^(G38-14),1)*MAX(1.02^(G38-29),1)*MAX(1.03^(G38-39),1) -> 222617.03 | K38: 29 | L38: =$L$6*($L$7^K38)*MAX(1.01^(K38-14), 1)*MAX(1.02^(K38-29), 1)*MAX(1.03^(K38-39), 1) -> 5.0194e+17 | S38: 29 | T38: =$T$6*($T$7^S38) -> 1.37261e+21 | W38: 29 | X38: =$X$6*($X$7^W38) -> 6.86304e+18 | AA38: 29 | AB38: =$AB$6*($AB$7^AA38) -> 3.21991e+34
G39: 30 | H39: =$H$6*($H$7^G39)*MAX(1.01^(G39-14),1)*MAX(1.02^(G39-29),1)*MAX(1.03^(G39-39),1) -> 344010.09 | K39: 30 | L39: =$L$6*($L$7^K39)*MAX(1.01^(K39-14), 1)*MAX(1.02^(K39-29), 1)*MAX(1.03^(K39-39), 1) -> 2.06839e+18 | S39: 30 | T39: =$T$6*($T$7^S39) -> 4.11782e+21 | W39: 30 | X39: MAXED | AA39: 30 | AB39: MAXED
G40: 31 | H40: =$H$6*($H$7^G40)*MAX(1.01^(G40-14),1)*MAX(1.02^(G40-29),1)*MAX(1.03^(G40-39),1) -> 531598.79 | K40: 31 | L40: =$L$6*($L$7^K40)*MAX(1.01^(K40-14), 1)*MAX(1.02^(K40-29), 1)*MAX(1.03^(K40-39), 1) -> 8.52344e+18 | S40: 31 | T40: =$T$6*($T$7^S40) -> 1.23535e+22 | X40: MAXED | AB40: MAXED
G41: 32 | H41: =$H$6*($H$7^G41)*MAX(1.01^(G41-14),1)*MAX(1.02^(G41-29),1)*MAX(1.03^(G41-39),1) -> 821479.62 | K41: 32 | L41: =$L$6*($L$7^K41)*MAX(1.01^(K41-14), 1)*MAX(1.02^(K41-29), 1)*MAX(1.03^(K41-39), 1) -> 3.51234e+19 | S41: 32 | T41: =$T$6*($T$7^S41) -> 3.70604e+22 | X41: MAXED | AB41: MAXED
G42: 33 | H42: =$H$6*($H$7^G42)*MAX(1.01^(G42-14),1)*MAX(1.02^(G42-29),1)*MAX(1.03^(G42-39),1) -> 1269432.5 | K42: 33 | L42: =$L$6*($L$7^K42)*MAX(1.01^(K42-14), 1)*MAX(1.02^(K42-29), 1)*MAX(1.03^(K42-39), 1) -> 1.44736e+20 | S42: 33 | T42: =$T$6*($T$7^S42) -> 1.11181e+23 | X42: MAXED | AB42: MAXED
G43: 34 | H43: =$H$6*($H$7^G43)*MAX(1.01^(G43-14),1)*MAX(1.02^(G43-29),1)*MAX(1.03^(G43-39),1) -> 1961654 | K43: 34 | L43: =$L$6*($L$7^K43)*MAX(1.01^(K43-14), 1)*MAX(1.02^(K43-29), 1)*MAX(1.03^(K43-39), 1) -> 5.9643e+20 | S43: 34 | T43: =$T$6*($T$7^S43) -> 3.33544e+23 | X43: MAXED | AB43: MAXED
G44: 35 | H44: =$H$6*($H$7^G44)*MAX(1.01^(G44-14),1)*MAX(1.02^(G44-29),1)*MAX(1.03^(G44-39),1) -> 3031343.9 | K44: 35 | L44: =$L$6*($L$7^K44)*MAX(1.01^(K44-14), 1)*MAX(1.02^(K44-29), 1)*MAX(1.03^(K44-39), 1) -> 2.45777e+21 | S44: 35 | T44: =$T$6*($T$7^S44) -> 1.00063e+24 | X44: MAXED | AB44: MAXED
G45: 36 | H45: =$H$6*($H$7^G45)*MAX(1.01^(G45-14),1)*MAX(1.02^(G45-29),1)*MAX(1.03^(G45-39),1) -> 4684335.7 | K45: 36 | L45: =$L$6*($L$7^K45)*MAX(1.01^(K45-14), 1)*MAX(1.02^(K45-29), 1)*MAX(1.03^(K45-39), 1) -> 1.0128e+22 | S45: 36 | T45: =$T$6*($T$7^S45) -> 3.00189e+24 | X45: MAXED | AB45: MAXED
G46: 37 | H46: =$H$6*($H$7^G46)*MAX(1.01^(G46-14),1)*MAX(1.02^(G46-29),1)*MAX(1.03^(G46-39),1) -> 7238704 | K46: 37 | L46: =$L$6*($L$7^K46)*MAX(1.01^(K46-14), 1)*MAX(1.02^(K46-29), 1)*MAX(1.03^(K46-39), 1) -> 4.17353e+22 | S46: 37 | T46: =$T$6*($T$7^S46) -> 9.00568e+24 | X46: MAXED | AB46: MAXED
G47: 38 | H47: =$H$6*($H$7^G47)*MAX(1.01^(G47-14),1)*MAX(1.02^(G47-29),1)*MAX(1.03^(G47-39),1) -> 11185969 | K47: 38 | L47: =$L$6*($L$7^K47)*MAX(1.01^(K47-14), 1)*MAX(1.02^(K47-29), 1)*MAX(1.03^(K47-39), 1) -> 1.71983e+23 | S47: 38 | T47: =$T$6*($T$7^S47) -> 2.7017e+25 | X47: MAXED | AB47: MAXED
G48: 39 | H48: =$H$6*($H$7^G48)*MAX(1.01^(G48-14),1)*MAX(1.02^(G48-29),1)*MAX(1.03^(G48-39),1) -> 17285678 | K48: 39 | L48: =$L$6*($L$7^K48)*MAX(1.01^(K48-14), 1)*MAX(1.02^(K48-29), 1)*MAX(1.03^(K48-39), 1) -> 7.08707e+23 | S48: 39 | T48: =$T$6*($T$7^S48) -> 8.10511e+25 | X48: MAXED | AB48: MAXED
G49: 40 | H49: =$H$6*($H$7^G49)*MAX(1.01^(G49-14),1)*MAX(1.02^(G49-29),1)*MAX(1.03^(G49-39),1) -> 27512905 | K49: 40 | L49: =$L$6*($L$7^K49)*MAX(1.01^(K49-14), 1)*MAX(1.02^(K49-29), 1)*MAX(1.03^(K49-39), 1) -> 3.00805e+24 | S49: 40 | T49: =$T$6*($T$7^S49) -> 2.43153e+26 | X49: MAXED | AB49: MAXED
G50: 41 | H50: =$H$6*($H$7^G50)*MAX(1.01^(G50-14),1)*MAX(1.02^(G50-29),1)*MAX(1.03^(G50-39),1) -> 43791163 | K50: 41 | L50: =$L$6*($L$7^K50)*MAX(1.01^(K50-14), 1)*MAX(1.02^(K50-29), 1)*MAX(1.03^(K50-39), 1) -> 1.27675e+25 | S50: 41 | T50: =$T$6*($T$7^S50) -> 7.2946e+26 | X50: MAXED | AB50: MAXED
...

Sheet InnovationData
B4: Innovation Quality Upgrade | G4: Studies/Study Bonus | K4: Cells Bonus | O4: MP Bonus | S4: Shards Bonus | W4: RP Bonus | AA4: AP Bonus
